Workbook

Sheet Orders_Working
A1: order_id | B1: order_date | C1: customer_id | D1: product_id | E1: sales_rep_id | F1: quantity | G1: unit_price | H1: discount_pct | I1: final_amount | J1: payment_status | K1: ship_city | L1: Category | M1: Sales Region | N1: Unit Cost | O1: Customer Segment | P1: Customer Age | Q1: Profit Margin | R1: Duplicate Check | S1: Product Active | T1: Customer Ref Check | U1: Standardized Ship City | V1: Bengaluru Grocery Order Value
A2: ORD-00001 | B2: 45549 | C2: CUST-0243 | D2: PROD-014 | E2: R007 | F2: 8 | G2: 3620 | H2: 15.4 | I2: 24500.16 | J2: Completed | K2: Pune | L2: =IFERROR(VLOOKUP(D2,Products!$A$2:$F$61,3,FALSE()),"") -> Apparel | M2: =IFERROR(VLOOKUP(E2,Sales_Reps!$A$2:$C$31,3,FALSE()),"") -> North | N2: =IFERROR(VLOOKUP(D2,Products!$A$2:$F$61,4,FALSE()),"") -> 2509 | O2: =IFERROR(VLOOKUP(C2,Customers!$A$2:$F$301,5,FALSE()),"") -> SMB | P2: =IFERROR(VLOOKUP(C2,Customers!$A$2:$F$301,3,FALSE()),"") -> 44 | Q2: =IFERROR((G2-N2)/G2,"") -> 0.30690608 | R2: =IF(AND(COUNTIF($A$2:$A$2047,A2)>1,COUNTIF($A$2:A2,A2)=1),1,0) -> 0 | S2: =IFERROR(VLOOKUP(D2,Products!$A$2:$F$61,6,FALSE()),"") -> TRUE | T2: =IF(COUNTIF(Customers!$A$2:$A$301,C2)=0,"Missing","OK") -> OK | U2: =IF(K2="","",PROPER(TRIM(K2))) -> Pune | V2: =IF(AND(U2="Bengaluru",L2="Grocery"),I2,0) -> 0
A3: ORD-00002 | B3: 45340 | C3: CUST-0202 | D3: PROD-020 | E3: R005 | F3: 2 | G3: 820 | H3: 10.8 | I3: 1462.88 | J3: Pending | K3: Chennai | L3: =IFERROR(VLOOKUP(D3,Products!$A$2:$F$61,3,FALSE()),"") -> Apparel | M3: =IFERROR(VLOOKUP(E3,Sales_Reps!$A$2:$C$31,3,FALSE()),"") -> North | N3: =IFERROR(VLOOKUP(D3,Products!$A$2:$F$61,4,FALSE()),"") -> 391 | O3: =IFERROR(VLOOKUP(C3,Customers!$A$2:$F$301,5,FALSE()),"") -> Retail | P3: =IFERROR(VLOOKUP(C3,Customers!$A$2:$F$301,3,FALSE()),"") -> 39 | Q3: =IFERROR((G3-N3)/G3,"") -> 0.52317073 | R3: =IF(AND(COUNTIF($A$2:$A$2047,A3)>1,COUNTIF($A$2:A3,A3)=1),1,0) -> 0 | S3: =IFERROR(VLOOKUP(D3,Products!$A$2:$F$61,6,FALSE()),"") -> TRUE | T3: =IF(COUNTIF(Customers!$A$2:$A$301,C3)=0,"Missing","OK") -> OK | U3: =IF(K3="","",PROPER(TRIM(K3))) -> Chennai | V3: =IF(AND(U3="Bengaluru",L3="Grocery"),I3,0) -> 0
A4: ORD-00003 | B4: 45371 | C4: CUST-0098 | D4: PROD-053 | E4: R014 | F4: 8 | G4: 470 | H4: 3.3 | I4: 3635.92 | J4: Pending | K4: Delhi | L4: =IFERROR(VLOOKUP(D4,Products!$A$2:$F$61,3,FALSE()),"") -> Sports | M4: =IFERROR(VLOOKUP(E4,Sales_Reps!$A$2:$C$31,3,FALSE()),"") -> South | N4: =IFERROR(VLOOKUP(D4,Products!$A$2:$F$61,4,FALSE()),"") -> 302 | O4: =IFERROR(VLOOKUP(C4,Customers!$A$2:$F$301,5,FALSE()),"") -> Retail | P4: =IFERROR(VLOOKUP(C4,Customers!$A$2:$F$301,3,FALSE()),"") -> 52 | Q4: =IFERROR((G4-N4)/G4,"") -> 0.35744681 | R4: =IF(AND(COUNTIF($A$2:$A$2047,A4)>1,COUNTIF($A$2:A4,A4)=1),1,0) -> 0 | S4: =IFERROR(VLOOKUP(D4,Products!$A$2:$F$61,6,FALSE()),"") -> FALSE | T4: =IF(COUNTIF(Customers!$A$2:$A$301,C4)=0,"Missing","OK") -> OK | U4: =IF(K4="","",PROPER(TRIM(K4))) -> Delhi | V4: =IF(AND(U4="Bengaluru",L4="Grocery"),I4,0) -> 0
A5: ORD-00004 | B5: 45413 | C5: CUST-0071 | D5: PROD-028 | E5: R006 | F5: 1 | G5: 3660 | H5: 15.7 | I5: 3085.38 | J5: Completed | K5: Delhi | L5: =IFERROR(VLOOKUP(D5,Products!$A$2:$F$61,3,FALSE()),"") -> Grocery | M5: =IFERROR(VLOOKUP(E5,Sales_Reps!$A$2:$C$31,3,FALSE()),"") -> North | N5: =IFERROR(VLOOKUP(D5,Products!$A$2:$F$61,4,FALSE()),"") -> 2214 | O5: =IFERROR(VLOOKUP(C5,Customers!$A$2:$F$301,5,FALSE()),"") -> Corporate | P5: =IFERROR(VLOOKUP(C5,Customers!$A$2:$F$301,3,FALSE()),"") -> 46 | Q5: =IFERROR((G5-N5)/G5,"") -> 0.39508197 | R5: =IF(AND(COUNTIF($A$2:$A$2047,A5)>1,COUNTIF($A$2:A5,A5)=1),1,0) -> 0 | S5: =IFERROR(VLOOKUP(D5,Products!$A$2:$F$61,6,FALSE()),"") -> FALSE | T5: =IF(COUNTIF(Customers!$A$2:$A$301,C5)=0,"Missing","OK") -> OK | U5: =IF(K5="","",PROPER(TRIM(K5))) -> Delhi | V5: =IF(AND(U5="Bengaluru",L5="Grocery"),I5,0) -> 0
A6: ORD-00005 | B6: 45611 | C6: CUST-0180 | D6: PROD-012 | E6: R008 | F6: 1 | G6: 3160 | H6: 26 | I6: 2338.4 | J6: Completed | K6: Chennai | L6: =IFERROR(VLOOKUP(D6,Products!$A$2:$F$61,3,FALSE()),"") -> Apparel | M6: =IFERROR(VLOOKUP(E6,Sales_Reps!$A$2:$C$31,3,FALSE()),"") -> North | N6: =IFERROR(VLOOKUP(D6,Products!$A$2:$F$61,4,FALSE()),"") -> 1886 | O6: =IFERROR(VLOOKUP(C6,Customers!$A$2:$F$301,5,FALSE()),"") -> Retail | P6: =IFERROR(VLOOKUP(C6,Customers!$A$2:$F$301,3,FALSE()),"") -> 36 | Q6: =IFERROR((G6-N6)/G6,"") -> 0.40316456 | R6: =IF(AND(COUNTIF($A$2:$A$2047,A6)>1,COUNTIF($A$2:A6,A6)=1),1,0) -> 0 | S6: =IFERROR(VLOOKUP(D6,Products!$A$2:$F$61,6,FALSE()),"") -> TRUE | T6: =IF(COUNTIF(Customers!$A$2:$A$301,C6)=0,"Missing","OK") -> OK | U6: =IF(K6="","",PROPER(TRIM(K6))) -> Chennai | V6: =IF(AND(U6="Bengaluru",L6="Grocery"),I6,0) -> 0
A7: ORD-00006 | B7: 45406 | C7: CUST-0275 | D7: PROD-032 | E7: R025 | F7: 4 | G7: 370 | H7: 29 | I7: 1050.8 | J7: Completed | K7: Mumbai | L7: =IFERROR(VLOOKUP(D7,Products!$A$2:$F$61,3,FALSE()),"") -> Home | M7: =IFERROR(VLOOKUP(E7,Sales_Reps!$A$2:$C$31,3,FALSE()),"") -> West | N7: =IFERROR(VLOOKUP(D7,Products!$A$2:$F$61,4,FALSE()),"") -> 288 | O7: =IFERROR(VLOOKUP(C7,Customers!$A$2:$F$301,5,FALSE()),"") -> Retail | P7: =IFERROR(VLOOKUP(C7,Customers!$A$2:$F$301,3,FALSE()),"") -> 36 | Q7: =IFERROR((G7-N7)/G7,"") -> 0.22162162 | R7: =IF(AND(COUNTIF($A$2:$A$2047,A7)>1,COUNTIF($A$2:A7,A7)=1),1,0) -> 0 | S7: =IFERROR(VLOOKUP(D7,Products!$A$2:$F$61,6,FALSE()),"") -> TRUE | T7: =IF(COUNTIF(Customers!$A$2:$A$301,C7)=0,"Missing","OK") -> OK | U7: =IF(K7="","",PROPER(TRIM(K7))) -> Mumbai | V7: =IF(AND(U7="Bengaluru",L7="Grocery"),I7,0) -> 0
A8: ORD-00007 | B8: 45455 | C8: CUST-0293 | D8: PROD-057 | E8: R024 | F8: 3 | G8: 960 | H8: 5.8 | I8: 2712.96 | J8: Completed | K8: Bengaluru | L8: =IFERROR(VLOOKUP(D8,Products!$A$2:$F$61,3,FALSE()),"") -> Sports | M8: =IFERROR(VLOOKUP(E8,Sales_Reps!$A$2:$C$31,3,FALSE()),"") -> West | N8: =IFERROR(VLOOKUP(D8,Products!$A$2:$F$61,4,FALSE()),"") -> 705 | O8: =IFERROR(VLOOKUP(C8,Customers!$A$2:$F$301,5,FALSE()),"") -> Retail | P8: =IFERROR(VLOOKUP(C8,Customers!$A$2:$F$301,3,FALSE()),"") -> 27 | Q8: =IFERROR((G8-N8)/G8,"") -> 0.265625 | R8: =IF(AND(COUNTIF($A$2:$A$2047,A8)>1,COUNTIF($A$2:A8,A8)=1),1,0) -> 0 | S8: =IFERROR(VLOOKUP(D8,Products!$A$2:$F$61,6,FALSE()),"") -> TRUE | T8: =IF(COUNTIF(Customers!$A$2:$A$301,C8)=0,"Missing","OK") -> OK | U8: =IF(K8="","",PROPER(TRIM(K8))) -> Bengaluru | V8: =IF(AND(U8="Bengaluru",L8="Grocery"),I8,0) -> 0
A9: ORD-00008 | B9: 45617 | C9: CUST-0281 | D9: PROD-007 | E9: R019 | F9: 8 | G9: 1430 | H9: 2.4 | I9: 11165.44 | J9: Completed | K9: Bengaluru | L9: =IFERROR(VLOOKUP(D9,Products!$A$2:$F$61,3,FALSE()),"") -> Electronics | M9: =IFERROR(VLOOKUP(E9,Sales_Reps!$A$2:$C$31,3,FALSE()),"") -> East | N9: =IFERROR(VLOOKUP(D9,Products!$A$2:$F$61,4,FALSE()),"") -> 861 | O9: =IFERROR(VLOOKUP(C9,Customers!$A$2:$F$301,5,FALSE()),"") -> Corporate | P9: =IFERROR(VLOOKUP(C9,Customers!$A$2:$F$301,3,FALSE()),"") -> 57 | Q9: =IFERROR((G9-N9)/G9,"") -> 0.3979021 | R9: =IF(AND(COUNTIF($A$2:$A$2047,A9)>1,COUNTIF($A$2:A9,A9)=1),1,0) -> 0 | S9: =IFERROR(VLOOKUP(D9,Products!$A$2:$F$61,6,FALSE()),"") -> TRUE | T9: =IF(COUNTIF(Customers!$A$2:$A$301,C9)=0,"Missing","OK") -> OK | U9: =IF(K9="","",PROPER(TRIM(K9))) -> Bengaluru | V9: =IF(AND(U9="Bengaluru",L9="Grocery"),I9,0) -> 0
A10: ORD-00009 | B10: 45549 | C10: CUST-0260 | D10: PROD-038 | E10: R008 | F10: 3 | G10: 5490 | H10: 14.2 | I10: 14131.26 | J10: Completed | K10: Bengaluru | L10: =IFERROR(VLOOKUP(D10,Products!$A$2:$F$61,3,FALSE()),"") -> Home | M10: =IFERROR(VLOOKUP(E10,Sales_Reps!$A$2:$C$31,3,FALSE()),"") -> North | N10: =IFERROR(VLOOKUP(D10,Products!$A$2:$F$61,4,FALSE()),"") -> 2549 | O10: =IFERROR(VLOOKUP(C10,Customers!$A$2:$F$301,5,FALSE()),"") -> Retail | P10: =IFERROR(VLOOKUP(C10,Customers!$A$2:$F$301,3,FALSE()),"") -> 42 | Q10: =IFERROR((G10-N10)/G10,"") -> 0.53570128 | R10: =IF(AND(COUNTIF($A$2:$A$2047,A10)>1,COUNTIF($A$2:A10,A10)=1),1,0) -> 0 | S10: =IFERROR(VLOOKUP(D10,Products!$A$2:$F$61,6,FALSE()),"") -> TRUE | T10: =IF(COUNTIF(Customers!$A$2:$A$301,C10)=0,"Missing","OK") -> OK | U10: =IF(K10="","",PROPER(TRIM(K10))) -> Bengaluru | V10: =IF(AND(U10="Bengaluru",L10="Grocery"),I10,0) -> 0
A11: ORD-00010 | B11: 45396 | C11: CUST-0147 | D11: PROD-030 | E11: R028 | F11: 3 | G11: 970 | H11: 1.2 | I11: 2875.08 | J11: Completed | K11: Pune | L11: =IFERROR(VLOOKUP(D11,Products!$A$2:$F$61,3,FALSE()),"") -> Grocery | M11: =IFERROR(VLOOKUP(E11,Sales_Reps!$A$2:$C$31,3,FALSE()),"") -> West | N11: =IFERROR(VLOOKUP(D11,Products!$A$2:$F$61,4,FALSE()),"") -> 434 | O11: =IFERROR(VLOOKUP(C11,Customers!$A$2:$F$301,5,FALSE()),"") -> Retail | P11: =IFERROR(VLOOKUP(C11,Customers!$A$2:$F$301,3,FALSE()),"") -> 56 | Q11: =IFERROR((G11-N11)/G11,"") -> 0.55257732 | R11: =IF(AND(COUNTIF($A$2:$A$2047,A11)>1,COUNTIF($A$2:A11,A11)=1),1,0) -> 0 | S11: =IFERROR(VLOOKUP(D11,Products!$A$2:$F$61,6,FALSE()),"") -> TRUE | T11: =IF(COUNTIF(Customers!$A$2:$A$301,C11)=0,"Missing","OK") -> OK | U11: =IF(K11="","",PROPER(TRIM(K11))) -> Pune | V11: =IF(AND(U11="Bengaluru",L11="Grocery"),I11,0) -> 0
A12: ORD-00011 | B12: 45560 | C12: CUST-0204 | D12: PROD-024 | E12: R010 | F12: 7 | G12: 2270 | H12: 7.1 | I12: 14761.81 | J12: Pending | K12: Hyderabad | L12: =IFERROR(VLOOKUP(D12,Products!$A$2:$F$61,3,FALSE()),"") -> Grocery | M12: =IFERROR(VLOOKUP(E12,Sales_Reps!$A$2:$C$31,3,FALSE()),"") -> South | N12: =IFERROR(VLOOKUP(D12,Products!$A$2:$F$61,4,FALSE()),"") -> 1203 | O12: =IFERROR(VLOOKUP(C12,Customers!$A$2:$F$301,5,FALSE()),"") -> Retail | P12: =IFERROR(VLOOKUP(C12,Customers!$A$2:$F$301,3,FALSE()),"") -> 60 | Q12: =IFERROR((G12-N12)/G12,"") -> 0.47004405 | R12: =IF(AND(COUNTIF($A$2:$A$2047,A12)>1,COUNTIF($A$2:A12,A12)=1),1,0) -> 0 | S12: =IFERROR(VLOOKUP(D12,Products!$A$2:$F$61,6,FALSE()),"") -> TRUE | T12: =IF(COUNTIF(Customers!$A$2:$A$301,C12)=0,"Missing","OK") -> OK | U12: =IF(K12="","",PROPER(TRIM(K12))) -> Hyderabad | V12: =IF(AND(U12="Bengaluru",L12="Grocery"),I12,0) -> 0
A13: ORD-00012 | B13: 45332 | C13: CUST-0147 | D13: PROD-010 | E13: R024 | F13: 9 | G13: 2640 | H13: 21.7 | I13: 18604.08 | J13: Completed | K13: Pune | L13: =IFERROR(VLOOKUP(D13,Products!$A$2:$F$61,3,FALSE()),"") -> Electronics | M13: =IFERROR(VLOOKUP(E13,Sales_Reps!$A$2:$C$31,3,FALSE()),"") -> West | N13: =IFERROR(VLOOKUP(D13,Products!$A$2:$F$61,4,FALSE()),"") -> 1149 | O13: =IFERROR(VLOOKUP(C13,Customers!$A$2:$F$301,5,FALSE()),"") -> Retail | P13: =IFERROR(VLOOKUP(C13,Customers!$A$2:$F$301,3,FALSE()),"") -> 56 | Q13: =IFERROR((G13-N13)/G13,"") -> 0.56477273 | R13: =IF(AND(COUNTIF($A$2:$A$2047,A13)>1,COUNTIF($A$2:A13,A13)=1),1,0) -> 0 | S13: =IFERROR(VLOOKUP(D13,Products!$A$2:$F$61,6,FALSE()),"") -> TRUE | T13: =IF(COUNTIF(Customers!$A$2:$A$301,C13)=0,"Missing","OK") -> OK | U13: =IF(K13="","",PROPER(TRIM(K13))) -> Pune | V13: =IF(AND(U13="Bengaluru",L13="Grocery"),I13,0) -> 0
... A2001: ORD-02000 | B2001: 45325 | C2001: CUST-0238 | D2001: PROD-034 | E2001: R023 | F2001: 6 | G2001: 5080 | H2001: 28.1 | I2001: 21915.12 | J2001: Completed | K2001: Delhi | L2001: =IFERROR(VLOOKUP(D2001,Products!$A$2:$F$61,3,FALSE()),"") -> Home | M2001: =IFERROR(VLOOKUP(E2001,Sales_Reps!$A$2:$C$31,3,FALSE()),"") -> East | N2001: =IFERROR(VLOOKUP(D2001,Products!$A$2:$F$61,4,FALSE()),"") -> 2459 | O2001: =IFERROR(VLOOKUP(C2001,Customers!$A$2:$F$301,5,FALSE()),"") -> Retail | P2001: =IFERROR(VLOOKUP(C2001,Customers!$A$2:$F$301,3,FALSE()),"") -> 49 | Q2001: =IFERROR((G2001-N2001)/G2001,"") -> 0.51594488 | R2001: =IF(AND(COUNTIF($A$2:$A$2047,A2001)>1,COUNTIF($A$2:A2001,A2001)=1),1,0) -> 0 | S2001: =IFERROR(VLOOKUP(D2001,Products!$A$2:$F$61,6,FALSE()),"") -> TRUE | T2001: =IF(COUNTIF(Customers!$A$2:$A$301,C2001)=0,"Missing","OK") -> OK | U2001: =IF(K2001="","",PROPER(TRIM(K2001))) -> Delhi | V2001: =IF(AND(U2001="Bengaluru",L2001="Grocery"),I2001,0) -> 0
L2002: =IFERROR(VLOOKUP(D2002,Products!$A$2:$F$61,3,FALSE()),"") | M2002: =IFERROR(VLOOKUP(E2002,Sales_Reps!$A$2:$C$31,3,FALSE()),"") | N2002: =IFERROR(VLOOKUP(D2002,Products!$A$2:$F$61,4,FALSE()),"") | O2002: =IFERROR(VLOOKUP(C2002,Customers!$A$2:$F$301,5,FALSE()),"") | P2002: =IFERROR(VLOOKUP(C2002,Customers!$A$2:$F$301,3,FALSE()),"") | Q2002: =IFERROR((G2002-N2002)/G2002,"") | R2002: =IF(AND(COUNTIF($A$2:$A$2047,A2002)>1,COUNTIF($A$2:A2002,A2002)=1),1,0) -> 0 | S2002: =IFERROR(VLOOKUP(D2002,Products!$A$2:$F$61,6,FALSE()),"") | T2002: =IF(COUNTIF(Customers!$A$2:$A$301,C2002)=0,"Missing","OK") -> Missing | U2002: =IF(K2002="","",PROPER(TRIM(K2002))) | V2002: =IF(AND(U2002="Bengaluru",L2002="Grocery"),I2002,0) -> 0
L2003: =IFERROR(VLOOKUP(D2003,Products!$A$2:$F$61,3,FALSE()),"") | M2003: =IFERROR(VLOOKUP(E2003,Sales_Reps!$A$2:$C$31,3,FALSE()),"") | N2003: =IFERROR(VLOOKUP(D2003,Products!$A$2:$F$61,4,FALSE()),"") | O2003: =IFERROR(VLOOKUP(C2003,Customers!$A$2:$F$301,5,FALSE()),"") | P2003: =IFERROR(VLOOKUP(C2003,Customers!$A$2:$F$301,3,FALSE()),"") | Q2003: =IFERROR((G2003-N2003)/G2003,"") | R2003: =IF(AND(COUNTIF($A$2:$A$2047,A2003)>1,COUNTIF($A$2:A2003,A2003)=1),1,0) -> 0 | S2003: =IFERROR(VLOOKUP(D2003,Products!$A$2:$F$61,6,FALSE()),"") | T2003: =IF(COUNTIF(Customers!$A$2:$A$301,C2003)=0,"Missing","OK") -> Missing | U2003: =IF(K2003="","",PROPER(TRIM(K2003))) | V2003: =IF(AND(U2003="Bengaluru",L2003="Grocery"),I2003,0) -> 0
L2004: =IFERROR(VLOOKUP(D2004,Products!$A$2:$F$61,3,FALSE()),"") | M2004: =IFERROR(VLOOKUP(E2004,Sales_Reps!$A$2:$C$31,3,FALSE()),"") | N2004: =IFERROR(VLOOKUP(D2004,Products!$A$2:$F$61,4,FALSE()),"") | O2004: =IFERROR(VLOOKUP(C2004,Customers!$A$2:$F$301,5,FALSE()),"") | P2004: =IFERROR(VLOOKUP(C2004,Customers!$A$2:$F$301,3,FALSE()),"") | Q2004: =IFERROR((G2004-N2004)/G2004,"") | R2004: =IF(AND(COUNTIF($A$2:$A$2047,A2004)>1,COUNTIF($A$2:A2004,A2004)=1),1,0) -> 0 | S2004: =IFERROR(VLOOKUP(D2004,Products!$A$2:$F$61,6,FALSE()),"") | T2004: =IF(COUNTIF(Customers!$A$2:$A$301,C2004)=0,"Missing","OK") -> Missing | U2004: =IF(K2004="","",PROPER(TRIM(K2004))) | V2004: =IF(AND(U2004="Bengaluru",L2004="Grocery"),I2004,0) -> 0
L2005: =IFERROR(VLOOKUP(D2005,Products!$A$2:$F$61,3,FALSE()),"") | M2005: =IFERROR(VLOOKUP(E2005,Sales_Reps!$A$2:$C$31,3,FALSE()),"") | N2005: =IFERROR(VLOOKUP(D2005,Products!$A$2:$F$61,4,FALSE()),"") | O2005: =IFERROR(VLOOKUP(C2005,Customers!$A$2:$F$301,5,FALSE()),"") | P2005: =IFERROR(VLOOKUP(C2005,Customers!$A$2:$F$301,3,FALSE()),"") | Q2005: =IFERROR((G2005-N2005)/G2005,"") | R2005: =IF(AND(COUNTIF($A$2:$A$2047,A2005)>1,COUNTIF($A$2:A2005,A2005)=1),1,0) -> 0 | S2005: =IFERROR(VLOOKUP(D2005,Products!$A$2:$F$61,6,FALSE()),"") | T2005: =IF(COUNTIF(Customers!$A$2:$A$301,C2005)=0,"Missing","OK") -> Missing | U2005: =IF(K2005="","",PROPER(TRIM(K2005))) | V2005: =IF(AND(U2005="Bengaluru",L2005="Grocery"),I2005,0) -> 0
L2006: =IFERROR(VLOOKUP(D2006,Products!$A$2:$F$61,3,FALSE()),"") | M2006: =IFERROR(VLOOKUP(E2006,Sales_Reps!$A$2:$C$31,3,FALSE()),"") | N2006: =IFERROR(VLOOKUP(D2006,Products!$A$2:$F$61,4,FALSE()),"") | O2006: =IFERROR(VLOOKUP(C2006,Customers!$A$2:$F$301,5,FALSE()),"") | P2006: =IFERROR(VLOOKUP(C2006,Customers!$A$2:$F$301,3,FALSE()),"") | Q2006: =IFERROR((G2006-N2006)/G2006,"") | R2006: =IF(AND(COUNTIF($A$2:$A$2047,A2006)>1,COUNTIF($A$2:A2006,A2006)=1),1,0) -> 0 | S2006: =IFERROR(VLOOKUP(D2006,Products!$A$2:$F$61,6,FALSE()),"") | T2006: =IF(COUNTIF(Customers!$A$2:$A$301,C2006)=0,"Missing","OK") -> Missing | U2006: =IF(K2006="","",PROPER(TRIM(K2006))) | V2006: =IF(AND(U2006="Bengaluru",L2006="Grocery"),I2006,0) -> 0
L2007: =IFERROR(VLOOKUP(D2007,Products!$A$2:$F$61,3,FALSE()),"") | M2007: =IFERROR(VLOOKUP(E2007,Sales_Reps!$A$2:$C$31,3,FALSE()),"") | N2007: =IFERROR(VLOOKUP(D2007,Products!$A$2:$F$61,4,FALSE()),"") | O2007: =IFERROR(VLOOKUP(C2007,Customers!$A$2:$F$301,5,FALSE()),"") | P2007: =IFERROR(VLOOKUP(C2007,Customers!$A$2:$F$301,3,FALSE()),"") | Q2007: =IFERROR((G2007-N2007)/G2007,"") | R2007: =IF(AND(COUNTIF($A$2:$A$2047,A2007)>1,COUNTIF($A$2:A2007,A2007)=1),1,0) -> 0 | S2007: =IFERROR(VLOOKUP(D2007,Products!$A$2:$F$61,6,FALSE()),"") | T2007: =IF(COUNTIF(Customers!$A$2:$A$301,C2007)=0,"Missing","OK") -> Missing | U2007: =IF(K2007="","",PROPER(TRIM(K2007))) | V2007: =IF(AND(U2007="Bengaluru",L2007="Grocery"),I2007,0) -> 0
L2008: =IFERROR(VLOOKUP(D2008,Products!$A$2:$F$61,3,FALSE()),"") | M2008: =IFERROR(VLOOKUP(E2008,Sales_Reps!$A$2:$C$31,3,FALSE()),"") | N2008: =IFERROR(VLOOKUP(D2008,Products!$A$2:$F$61,4,FALSE()),"") | O2008: =IFERROR(VLOOKUP(C2008,Customers!$A$2:$F$301,5,FALSE()),"") | P2008: =IFERROR(VLOOKUP(C2008,Customers!$A$2:$F$301,3,FALSE()),"") | Q2008: =IFERROR((G2008-N2008)/G2008,"") | R2008: =IF(AND(COUNTIF($A$2:$A$2047,A2008)>1,COUNTIF($A$2:A2008,A2008)=1),1,0) -> 0 | S2008: =IFERROR(VLOOKUP(D2008,Products!$A$2:$F$61,6,FALSE()),"") | T2008: =IF(COUNTIF(Customers!$A$2:$A$301,C2008)=0,"Missing","OK") -> Missing | U2008: =IF(K2008="","",PROPER(TRIM(K2008))) | V2008: =IF(AND(U2008="Bengaluru",L2008="Grocery"),I2008,0) -> 0
L2009: =IFERROR(VLOOKUP(D2009,Products!$A$2:$F$61,3,FALSE()),"") | M2009: =IFERROR(VLOOKUP(E2009,Sales_Reps!$A$2:$C$31,3,FALSE()),"") | N2009: =IFERROR(VLOOKUP(D2009,Products!$A$2:$F$61,4,FALSE()),"") | O2009: =IFERROR(VLOOKUP(C2009,Customers!$A$2:$F$301,5,FALSE()),"") | P2009: =IFERROR(VLOOKUP(C2009,Customers!$A$2:$F$301,3,FALSE()),"") | Q2009: =IFERROR((G2009-N2009)/G2009,"") | R2009: =IF(AND(COUNTIF($A$2:$A$2047,A2009)>1,COUNTIF($A$2:A2009,A2009)=1),1,0) -> 0 | S2009: =IFERROR(VLOOKUP(D2009,Products!$A$2:$F$61,6,FALSE()),"") | T2009: =IF(COUNTIF(Customers!$A$2:$A$301,C2009)=0,"Missing","OK") -> Missing | U2009: =IF(K2009="","",PROPER(TRIM(K2009))) | V2009: =IF(AND(U2009="Bengaluru",L2009="Grocery"),I2009,0) -> 0
L2010: =IFERROR(VLOOKUP(D2010,Products!$A$2:$F$61,3,FALSE()),"") | M2010: =IFERROR(VLOOKUP(E2010,Sales_Reps!$A$2:$C$31,3,FALSE()),"") | N2010: =IFERROR(VLOOKUP(D2010,Products!$A$2:$F$61,4,FALSE()),"") | O2010: =IFERROR(VLOOKUP(C2010,Customers!$A$2:$F$301,5,FALSE()),"") | P2010: =IFERROR(VLOOKUP(C2010,Customers!$A$2:$F$301,3,FALSE()),"") | Q2010: =IFERROR((G2010-N2010)/G2010,"") | R2010: =IF(AND(COUNTIF($A$2:$A$2047,A2010)>1,COUNTIF($A$2:A2010,A2010)=1),1,0) -> 0 | S2010: =IFERROR(VLOOKUP(D2010,Products!$A$2:$F$61,6,FALSE()),"") | T2010: =IF(COUNTIF(Customers!$A$2:$A$301,C2010)=0,"Missing","OK") -> Missing | U2010: =IF(K2010="","",PROPER(TRIM(K2010))) | V2010: =IF(AND(U2010="Bengaluru",L2010="Grocery"),I2010,0) -> 0
L2011: =IFERROR(VLOOKUP(D2011,Products!$A$2:$F$61,3,FALSE()),"") | M2011: =IFERROR(VLOOKUP(E2011,Sales_Reps!$A$2:$C$31,3,FALSE()),"") | N2011: =IFERROR(VLOOKUP(D2011,Products!$A$2:$F$61,4,FALSE()),"") | O2011: =IFERROR(VLOOKUP(C2011,Customers!$A$2:$F$301,5,FALSE()),"") | P2011: =IFERROR(VLOOKUP(C2011,Customers!$A$2:$F$301,3,FALSE()),"") | Q2011: =IFERROR((G2011-N2011)/G2011,"") | R2011: =IF(AND(COUNTIF($A$2:$A$2047,A2011)>1,COUNTIF($A$2:A2011,A2011)=1),1,0) -> 0 | S2011: =IFERROR(VLOOKUP(D2011,Products!$A$2:$F$61,6,FALSE()),"") | T2011: =IF(COUNTIF(Customers!$A$2:$A$301,C2011)=0,"Missing","OK") -> Missing | U2011: =IF(K2011="","",PROPER(TRIM(K2011))) | V2011: =IF(AND(U2011="Bengaluru",L2011="Grocery"),I2011,0) -> 0
L2012: =IFERROR(VLOOKUP(D2012,Products!$A$2:$F$61,3,FALSE()),"") | M2012: =IFERROR(VLOOKUP(E2012,Sales_Reps!$A$2:$C$31,3,FALSE()),"") | N2012: =IFERROR(VLOOKUP(D2012,Products!$A$2:$F$61,4,FALSE()),"") | O2012: =IFERROR(VLOOKUP(C2012,Customers!$A$2:$F$301,5,FALSE()),"") | P2012: =IFERROR(VLOOKUP(C2012,Customers!$A$2:$F$301,3,FALSE()),"") | Q2012: =IFERROR((G2012-N2012)/G2012,"") | R2012: =IF(AND(COUNTIF($A$2:$A$2047,A2012)>1,COUNTIF($A$2:A2012,A2012)=1),1,0) -> 0 | S2012: =IFERROR(VLOOKUP(D2012,Products!$A$2:$F$61,6,FALSE()),"") | T2012: =IF(COUNTIF(Customers!$A$2:$A$301,C2012)=0,"Missing","OK") -> Missing | U2012: =IF(K2012="","",PROPER(TRIM(K2012))) | V2012: =IF(AND(U2012="Bengaluru",L2012="Grocery"),I2012,0) -> 0
L2013: =IFERROR(VLOOKUP(D2013,Products!$A$2:$F$61,3,FALSE()),"") | M2013: =IFERROR(VLOOKUP(E2013,Sales_Reps!$A$2:$C$31,3,FALSE()),"") | N2013: =IFERROR(VLOOKUP(D2013,Products!$A$2:$F$61,4,FALSE()),"") | O2013: =IFERROR(VLOOKUP(C2013,Customers!$A$2:$F$301,5,FALSE()),"") | P2013: =IFERROR(VLOOKUP(C2013,Customers!$A$2:$F$301,3,FALSE()),"") | Q2013: =IFERROR((G2013-N2013)/G2013,"") | R2013: =IF(AND(COUNTIF($A$2:$A$2047,A2013)>1,COUNTIF($A$2:A2013,A2013)=1),1,0) -> 0 | S2013: =IFERROR(VLOOKUP(D2013,Products!$A$2:$F$61,6,FALSE()),"") | T2013: =IF(COUNTIF(Customers!$A$2:$A$301,C2013)=0,"Missing","OK") -> Missing | U2013: =IF(K2013="","",PROPER(TRIM(K2013))) | V2013: =IF(AND(U2013="Bengaluru",L2013="Grocery"),I2013,0) -> 0
... L2047: =IFERROR(VLOOKUP(D2047,Products!$A$2:$F$61,3,FALSE()),"") | M2047: =IFERROR(VLOOKUP(E2047,Sales_Reps!$A$2:$C$31,3,FALSE()),"") | N2047: =IFERROR(VLOOKUP(D2047,Products!$A$2:$F$61,4,FALSE()),"") | O2047: =IFERROR(VLOOKUP(C2047,Customers!$A$2:$F$301,5,FALSE()),"") | P2047: =IFERROR(VLOOKUP(C2047,Customers!$A$2:$F$301,3,FALSE()),"") | Q2047: =IFERROR((G2047-N2047)/G2047,"") | R2047: =IF(AND(COUNTIF($A$2:$A$2047,A2047)>1,COUNTIF($A$2:A2047,A2047)=1),1,0) -> 0 | S2047: =IFERROR(VLOOKUP(D2047,Products!$A$2:$F$61,6,FALSE()),"") | T2047: =IF(COUNTIF(Customers!$A$2:$A$301,C2047)=0,"Missing","OK") -> Missing | U2047: =IF(K2047="","",PROPER(TRIM(K2047))) | V2047: =IF(AND(U2047="Bengaluru",L2047="Grocery"),I2047,0) -> 0

Sheet README
A1: THE UNLOX ACADEMY - DA/DS TRACK
A2: Excel Minor Project - Sales Operations Analytics
A3: Interview-Grade Data Analytics Assessment · 100 Marks
A5: THE SCENARIO
A6: You have just joined the analytics team at a fast-growing multi-category retailer operating across 6 Indian cities.
A7: The head of sales has handed you 5 raw data files - Orders, Customers, Products, Sales Reps, and Targets - and asked
A8: you to answer a set of business questions before the leadership review tomorrow morning.
A10: The data is REAL-WORLD messy: duplicates, missing references, inconsistent case, invalid records, discontinued SKUs.
A11: Part of the assessment is spotting and handling these issues correctly. A wrong-looking answer isn't always wrong -
A12: sometimes the data itself is telling a story.
A14: RULES OF THE ASSESSMENT
A15: 1. Write your answer in the YELLOW cells on each question sheet. Empty answer cell = 0 marks.
... A22: MARKS DISTRIBUTION
A23: Section | B23: Topic | C23: Questions | D23: Marks
A24: Q1 | B24: Lookup Functions (VLOOKUP, INDEX-MATCH, chained lookups) | C24: 8 | D24: 25
A25: Q2 | B25: Data Cleaning & Quality Diagnostics | C25: 6 | D25: 20
A26: Q3 | B26: Conditional Aggregation (SUMIFS, COUNTIFS, IF logic) | C26: 6 | D26: 25
A27: Q4 | B27: Pivot Tables (2D pivots, % of total, calculated fields) | C27: 5 | D27: 20
A28: Q5 | B28: Advanced (Ranking, Running Totals, Multi-condition) | C28: 5 | D28: 10
B29: TOTAL | C29: 30 | D29: 100
A32: PERFORMANCE TIERS
A33: Marks | B33: Tier | C33: Interview Verdict
A34: 85 - 100 | B34: Excellent | C34: Round 1 clear - Excel not a concern
A35: 70 - 84 | B35: Good | C35: Round 1 clear with minor gaps
A36: 55 - 69 | B36: Borderline | C36: Round 1 uncertain - needs revision
A37: 40 - 54 | B37: Weak | C37: Round 1 likely reject - 2 weeks of practice needed
A38: < 40 | B38: Insufficient | C38: Round 1 reject - foundational gaps
A41: DATA SHEETS OVERVIEW
A42: Sheet | B42: Rows | C42: Key Columns | D42: Joins to
A43: Orders | B43: ~2000 | C43: order_id, order_date, customer_id, product_id, sales_rep_id, quantity, unit_price, discount_pct, final_amount, payment_status, ship_city | D43: All others
A44: Customers | B44: 300 | C44: customer_id (PK), customer_name, age, city, segment, signup_date | D44: Orders via customer_id
A45: Products | B45: 60 | C45: product_id (PK), product_name, category, unit_cost, unit_price, is_active | D45: Orders via product_id
A46: Sales_Reps | B46: 30 | C46: rep_id (PK), rep_name, region, hire_date, team_lead_id | D46: Orders via sales_rep_id, self-join via team_lead_id
A47: Targets | B47: 30 × 12 | C47: rep_id (PK), Jan-24 through Dec-24 monthly target values | D47: Sales_Reps via rep_id

Sheet Orders
A1: order_id | B1: order_date | C1: customer_id | D1: product_id | E1: sales_rep_id | F1: quantity | G1: unit_price | H1: discount_pct | I1: final_amount | J1: payment_status | K1: ship_city | L1: Category | M1: Sales Region | N1: Unit Cost | O1: Customer Segment | P1: Customer Age | Q1: Profit Margin | R1: Duplicate Check | S1: Product Active | T1: Customer Ref Check | U1: Standardized Ship City | V1: Bengaluru Grocery Order Value
A2: ORD-00001 | B2: 45549 | C2: CUST-0243 | D2: PROD-014 | E2: R007 | F2: 8 | G2: 3620 | H2: 15.4 | I2: 24500.16 | J2: Completed | K2: Pune | L2: =IFERROR(VLOOKUP(D2,Products!$A$2:$F$61,3,FALSE()),"") -> Apparel | M2: =IFERROR(VLOOKUP(E2,Sales_Reps!$A$2:$C$31,3,FALSE()),"") -> North | N2: =IFERROR(VLOOKUP(D2,Products!$A$2:$F$61,4,FALSE()),"") -> 2509 | O2: =IFERROR(VLOOKUP(C2,Customers!$A$2:$F$301,5,FALSE()),"") -> SMB | P2: =IFERROR(VLOOKUP(C2,Customers!$A$2:$F$301,3,FALSE()),"") -> 44 | Q2: =IFERROR((G2-N2)/G2,"") -> 0.30690608 | R2: =IF(AND(COUNTIF($A$2:$A$2027,A2)>1,COUNTIF($A$2:A2,A2)=1),1,0) -> 0 | S2: =IFERROR(VLOOKUP(D2,Products!$A$2:$F$61,6,FALSE()),"") -> TRUE | T2: =IF(COUNTIF(Customers!$A$2:$A$301,C2)=0,"Missing","OK") -> OK | U2: =IF(K2="","",PROPER(TRIM(K2))) -> Pune | V2: =IF(AND(U2="Bengaluru",L2="Grocery"),I2,0) -> 0
A3: ORD-00002 | B3: 45340 | C3: CUST-0202 | D3: PROD-020 | E3: R005 | F3: 2 | G3: 820 | H3: 10.8 | I3: 1462.88 | J3: Pending | K3: Chennai | L3: =IFERROR(VLOOKUP(D3,Products!$A$2:$F$61,3,FALSE()),"") -> Apparel | M3: =IFERROR(VLOOKUP(E3,Sales_Reps!$A$2:$C$31,3,FALSE()),"") -> North | N3: =IFERROR(VLOOKUP(D3,Products!$A$2:$F$61,4,FALSE()),"") -> 391 | O3: =IFERROR(VLOOKUP(C3,Customers!$A$2:$F$301,5,FALSE()),"") -> Retail | P3: =IFERROR(VLOOKUP(C3,Customers!$A$2:$F$301,3,FALSE()),"") -> 39 | Q3: =IFERROR((G3-N3)/G3,"") -> 0.52317073 | R3: =IF(AND(COUNTIF($A$2:$A$2027,A3)>1,COUNTIF($A$2:A3,A3)=1),1,0) -> 0 | S3: =IFERROR(VLOOKUP(D3,Products!$A$2:$F$61,6,FALSE()),"") -> TRUE | T3: =IF(COUNTIF(Customers!$A$2:$A$301,C3)=0,"Missing","OK") -> OK | U3: =IF(K3="","",PROPER(TRIM(K3))) -> Chennai | V3: =IF(AND(U3="Bengaluru",L3="Grocery"),I3,0) -> 0
A4: ORD-00003 | B4: 45371 | C4: CUST-0098 | D4: PROD-053 | E4: R014 | F4: 8 | G4: 470 | H4: 3.3 | I4: 3635.92 | J4: Pending | K4: Delhi | L4: =IFERROR(VLOOKUP(D4,Products!$A$2:$F$61,3,FALSE()),"") -> Sports | M4: =IFERROR(VLOOKUP(E4,Sales_Reps!$A$2:$C$31,3,FALSE()),"") -> South | N4: =IFERROR(VLOOKUP(D4,Products!$A$2:$F$61,4,FALSE()),"") -> 302 | O4: =IFERROR(VLOOKUP(C4,Customers!$A$2:$F$301,5,FALSE()),"") -> Retail | P4: =IFERROR(VLOOKUP(C4,Customers!$A$2:$F$301,3,FALSE()),"") -> 52 | Q4: =IFERROR((G4-N4)/G4,"") -> 0.35744681 | R4: =IF(AND(COUNTIF($A$2:$A$2027,A4)>1,COUNTIF($A$2:A4,A4)=1),1,0) -> 0 | S4: =IFERROR(VLOOKUP(D4,Products!$A$2:$F$61,6,FALSE()),"") -> FALSE | T4: =IF(COUNTIF(Customers!$A$2:$A$301,C4)=0,"Missing","OK") -> OK | U4: =IF(K4="","",PROPER(TRIM(K4))) -> Delhi | V4: =IF(AND(U4="Bengaluru",L4="Grocery"),I4,0) -> 0
A5: ORD-00004 | B5: 45413 | C5: CUST-0071 | D5: PROD-028 | E5: R006 | F5: 1 | G5: 3660 | H5: 15.7 | I5: 3085.38 | J5: Completed | K5: Delhi | L5: =IFERROR(VLOOKUP(D5,Products!$A$2:$F$61,3,FALSE()),"") -> Grocery | M5: =IFERROR(VLOOKUP(E5,Sales_Reps!$A$2:$C$31,3,FALSE()),"") -> North | N5: =IFERROR(VLOOKUP(D5,Products!$A$2:$F$61,4,FALSE()),"") -> 2214 | O5: =IFERROR(VLOOKUP(C5,Customers!$A$2:$F$301,5,FALSE()),"") -> Corporate | P5: =IFERROR(VLOOKUP(C5,Customers!$A$2:$F$301,3,FALSE()),"") -> 46 | Q5: =IFERROR((G5-N5)/G5,"") -> 0.39508197 | R5: =IF(AND(COUNTIF($A$2:$A$2027,A5)>1,COUNTIF($A$2:A5,A5)=1),1,0) -> 0 | S5: =IFERROR(VLOOKUP(D5,Products!$A$2:$F$61,6,FALSE()),"") -> FALSE | T5: =IF(COUNTIF(Customers!$A$2:$A$301,C5)=0,"Missing","OK") -> OK | U5: =IF(K5="","",PROPER(TRIM(K5))) -> Delhi | V5: =IF(AND(U5="Bengaluru",L5="Grocery"),I5,0) -> 0
A6: ORD-00005 | B6: 45611 | C6: CUST-0180 | D6: PROD-012 | E6: R008 | F6: 1 | G6: 3160 | H6: 26 | I6: 2338.4 | J6: Completed | K6: Chennai | L6: =IFERROR(VLOOKUP(D6,Products!$A$2:$F$61,3,FALSE()),"") -> Apparel | M6: =IFERROR(VLOOKUP(E6,Sales_Reps!$A$2:$C$31,3,FALSE()),"") -> North | N6: =IFERROR(VLOOKUP(D6,Products!$A$2:$F$61,4,FALSE()),"") -> 1886 | O6: =IFERROR(VLOOKUP(C6,Customers!$A$2:$F$301,5,FALSE()),"") -> Retail | P6: =IFERROR(VLOOKUP(C6,Customers!$A$2:$F$301,3,FALSE()),"") -> 36 | Q6: =IFERROR((G6-N6)/G6,"") -> 0.40316456 | R6: =IF(AND(COUNTIF($A$2:$A$2027,A6)>1,COUNTIF($A$2:A6,A6)=1),1,0) -> 0 | S6: =IFERROR(VLOOKUP(D6,Products!$A$2:$F$61,6,FALSE()),"") -> TRUE | T6: =IF(COUNTIF(Customers!$A$2:$A$301,C6)=0,"Missing","OK") -> OK | U6: =IF(K6="","",PROPER(TRIM(K6))) -> Chennai | V6: =IF(AND(U6="Bengaluru",L6="Grocery"),I6,0) -> 0
A7: ORD-00006 | B7: 45406 | C7: CUST-0275 | D7: PROD-032 | E7: R025 | F7: 4 | G7: 370 | H7: 29 | I7: 1050.8 | J7: Completed | K7: Mumbai | L7: =IFERROR(VLOOKUP(D7,Products!$A$2:$F$61,3,FALSE()),"") -> Home | M7: =IFERROR(VLOOKUP(E7,Sales_Reps!$A$2:$C$31,3,FALSE()),"") -> West | N7: =IFERROR(VLOOKUP(D7,Products!$A$2:$F$61,4,FALSE()),"") -> 288 | O7: =IFERROR(VLOOKUP(C7,Customers!$A$2:$F$301,5,FALSE()),"") -> Retail | P7: =IFERROR(VLOOKUP(C7,Customers!$A$2:$F$301,3,FALSE()),"") -> 36 | Q7: =IFERROR((G7-N7)/G7,"") -> 0.22162162 | R7: =IF(AND(COUNTIF($A$2:$A$2027,A7)>1,COUNTIF($A$2:A7,A7)=1),1,0) -> 0 | S7: =IFERROR(VLOOKUP(D7,Products!$A$2:$F$61,6,FALSE()),"") -> TRUE | T7: =IF(COUNTIF(Customers!$A$2:$A$301,C7)=0,"Missing","OK") -> OK | U7: =IF(K7="","",PROPER(TRIM(K7))) -> Mumbai | V7: =IF(AND(U7="Bengaluru",L7="Grocery"),I7,0) -> 0
A8: ORD-00007 | B8: 45455 | C8: CUST-0293 | D8: PROD-057 | E8: R024 | F8: 3 | G8: 960 | H8: 5.8 | I8: 2712.96 | J8: Completed | K8: Bengaluru | L8: =IFERROR(VLOOKUP(D8,Products!$A$2:$F$61,3,FALSE()),"") -> Sports | M8: =IFERROR(VLOOKUP(E8,Sales_Reps!$A$2:$C$31,3,FALSE()),"") -> West | N8: =IFERROR(VLOOKUP(D8,Products!$A$2:$F$61,4,FALSE()),"") -> 705 | O8: =IFERROR(VLOOKUP(C8,Customers!$A$2:$F$301,5,FALSE()),"") -> Retail | P8: =IFERROR(VLOOKUP(C8,Customers!$A$2:$F$301,3,FALSE()),"") -> 27 | Q8: =IFERROR((G8-N8)/G8,"") -> 0.265625 | R8: =IF(AND(COUNTIF($A$2:$A$2027,A8)>1,COUNTIF($A$2:A8,A8)=1),1,0) -> 0 | S8: =IFERROR(VLOOKUP(D8,Products!$A$2:$F$61,6,FALSE()),"") -> TRUE | T8: =IF(COUNTIF(Customers!$A$2:$A$301,C8)=0,"Missing","OK") -> OK | U8: =IF(K8="","",PROPER(TRIM(K8))) -> Bengaluru | V8: =IF(AND(U8="Bengaluru",L8="Grocery"),I8,0) -> 0
A9: ORD-00008 | B9: 45617 | C9: CUST-0281 | D9: PROD-007 | E9: R019 | F9: 8 | G9: 1430 | H9: 2.4 | I9: 11165.44 | J9: Completed | K9: Bengaluru | L9: =IFERROR(VLOOKUP(D9,Products!$A$2:$F$61,3,FALSE()),"") -> Electronics | M9: =IFERROR(VLOOKUP(E9,Sales_Reps!$A$2:$C$31,3,FALSE()),"") -> East | N9: =IFERROR(VLOOKUP(D9,Products!$A$2:$F$61,4,FALSE()),"") -> 861 | O9: =IFERROR(VLOOKUP(C9,Customers!$A$2:$F$301,5,FALSE()),"") -> Corporate | P9: =IFERROR(VLOOKUP(C9,Customers!$A$2:$F$301,3,FALSE()),"") -> 57 | Q9: =IFERROR((G9-N9)/G9,"") -> 0.3979021 | R9: =IF(AND(COUNTIF($A$2:$A$2027,A9)>1,COUNTIF($A$2:A9,A9)=1),1,0) -> 0 | S9: =IFERROR(VLOOKUP(D9,Products!$A$2:$F$61,6,FALSE()),"") -> TRUE | T9: =IF(COUNTIF(Customers!$A$2:$A$301,C9)=0,"Missing","OK") -> OK | U9: =IF(K9="","",PROPER(TRIM(K9))) -> Bengaluru | V9: =IF(AND(U9="Bengaluru",L9="Grocery"),I9,0) -> 0
A10: ORD-00009 | B10: 45549 | C10: CUST-0260 | D10: PROD-038 | E10: R008 | F10: 3 | G10: 5490 | H10: 14.2 | I10: 14131.26 | J10: Completed | K10: Bengaluru | L10: =IFERROR(VLOOKUP(D10,Products!$A$2:$F$61,3,FALSE()),"") -> Home | M10: =IFERROR(VLOOKUP(E10,Sales_Reps!$A$2:$C$31,3,FALSE()),"") -> North | N10: =IFERROR(VLOOKUP(D10,Products!$A$2:$F$61,4,FALSE()),"") -> 2549 | O10: =IFERROR(VLOOKUP(C10,Customers!$A$2:$F$301,5,FALSE()),"") -> Retail | P10: =IFERROR(VLOOKUP(C10,Customers!$A$2:$F$301,3,FALSE()),"") -> 42 | Q10: =IFERROR((G10-N10)/G10,"") -> 0.53570128 | R10: =IF(AND(COUNTIF($A$2:$A$2027,A10)>1,COUNTIF($A$2:A10,A10)=1),1,0) -> 0 | S10: =IFERROR(VLOOKUP(D10,Products!$A$2:$F$61,6,FALSE()),"") -> TRUE | T10: =IF(COUNTIF(Customers!$A$2:$A$301,C10)=0,"Missing","OK") -> OK | U10: =IF(K10="","",PROPER(TRIM(K10))) -> Bengaluru | V10: =IF(AND(U10="Bengaluru",L10="Grocery"),I10,0) -> 0
A11: ORD-00010 | B11: 45396 | C11: CUST-0147 | D11: PROD-030 | E11: R028 | F11: 3 | G11: 970 | H11: 1.2 | I11: 2875.08 | J11: Completed | K11: Pune | L11: =IFERROR(VLOOKUP(D11,Products!$A$2:$F$61,3,FALSE()),"") -> Grocery | M11: =IFERROR(VLOOKUP(E11,Sales_Reps!$A$2:$C$31,3,FALSE()),"") -> West | N11: =IFERROR(VLOOKUP(D11,Products!$A$2:$F$61,4,FALSE()),"") -> 434 | O11: =IFERROR(VLOOKUP(C11,Customers!$A$2:$F$301,5,FALSE()),"") -> Retail | P11: =IFERROR(VLOOKUP(C11,Customers!$A$2:$F$301,3,FALSE()),"") -> 56 | Q11: =IFERROR((G11-N11)/G11,"") -> 0.55257732 | R11: =IF(AND(COUNTIF($A$2:$A$2027,A11)>1,COUNTIF($A$2:A11,A11)=1),1,0) -> 0 | S11: =IFERROR(VLOOKUP(D11,Products!$A$2:$F$61,6,FALSE()),"") -> TRUE | T11: =IF(COUNTIF(Customers!$A$2:$A$301,C11)=0,"Missing","OK") -> OK | U11: =IF(K11="","",PROPER(TRIM(K11))) -> Pune | V11: =IF(AND(U11="Bengaluru",L11="Grocery"),I11,0) -> 0
A12: ORD-00011 | B12: 45560 | C12: CUST-0204 | D12: PROD-024 | E12: R010 | F12: 7 | G12: 2270 | H12: 7.1 | I12: 14761.81 | J12: Pending | K12: Hyderabad | L12: =IFERROR(VLOOKUP(D12,Products!$A$2:$F$61,3,FALSE()),"") -> Grocery | M12: =IFERROR(VLOOKUP(E12,Sales_Reps!$A$2:$C$31,3,FALSE()),"") -> South | N12: =IFERROR(VLOOKUP(D12,Products!$A$2:$F$61,4,FALSE()),"") -> 1203 | O12: =IFERROR(VLOOKUP(C12,Customers!$A$2:$F$301,5,FALSE()),"") -> Retail | P12: =IFERROR(VLOOKUP(C12,Customers!$A$2:$F$301,3,FALSE()),"") -> 60 | Q12: =IFERROR((G12-N12)/G12,"") -> 0.47004405 | R12: =IF(AND(COUNTIF($A$2:$A$2027,A12)>1,COUNTIF($A$2:A12,A12)=1),1,0) -> 0 | S12: =IFERROR(VLOOKUP(D12,Products!$A$2:$F$61,6,FALSE()),"") -> TRUE | T12: =IF(COUNTIF(Customers!$A$2:$A$301,C12)=0,"Missing","OK") -> OK | U12: =IF(K12="","",PROPER(TRIM(K12))) -> Hyderabad | V12: =IF(AND(U12="Bengaluru",L12="Grocery"),I12,0) -> 0
A13: ORD-00012 | B13: 45332 | C13: CUST-0147 | D13: PROD-010 | E13: R024 | F13: 9 | G13: 2640 | H13: 21.7 | I13: 18604.08 | J13: Completed | K13: Pune | L13: =IFERROR(VLOOKUP(D13,Products!$A$2:$F$61,3,FALSE()),"") -> Electronics | M13: =IFERROR(VLOOKUP(E13,Sales_Reps!$A$2:$C$31,3,FALSE()),"") -> West | N13: =IFERROR(VLOOKUP(D13,Products!$A$2:$F$61,4,FALSE()),"") -> 1149 | O13: =IFERROR(VLOOKUP(C13,Customers!$A$2:$F$301,5,FALSE()),"") -> Retail | P13: =IFERROR(VLOOKUP(C13,Customers!$A$2:$F$301,3,FALSE()),"") -> 56 | Q13: =IFERROR((G13-N13)/G13,"") -> 0.56477273 | R13: =IF(AND(COUNTIF($A$2:$A$2027,A13)>1,COUNTIF($A$2:A13,A13)=1),1,0) -> 0 | S13: =IFERROR(VLOOKUP(D13,Products!$A$2:$F$61,6,FALSE()),"") -> TRUE | T13: =IF(COUNTIF(Customers!$A$2:$A$301,C13)=0,"Missing","OK") -> OK | U13: =IF(K13="","",PROPER(TRIM(K13))) -> Pune | V13: =IF(AND(U13="Bengaluru",L13="Grocery"),I13,0) -> 0
... A2001: ORD-02000 | B2001: 45325 | C2001: CUST-0238 | D2001: PROD-034 | E2001: R023 | F2001: 6 | G2001: 5080 | H2001: 28.1 | I2001: 21915.12 | J2001: Completed | K2001: Delhi | L2001: =IFERROR(VLOOKUP(D2001,Products!$A$2:$F$61,3,FALSE()),"") -> Home | M2001: =IFERROR(VLOOKUP(E2001,Sales_Reps!$A$2:$C$31,3,FALSE()),"") -> East | N2001: =IFERROR(VLOOKUP(D2001,Products!$A$2:$F$61,4,FALSE()),"") -> 2459 | O2001: =IFERROR(VLOOKUP(C2001,Customers!$A$2:$F$301,5,FALSE()),"") -> Retail | P2001: =IFERROR(VLOOKUP(C2001,Customers!$A$2:$F$301,3,FALSE()),"") -> 49 | Q2001: =IFERROR((G2001-N2001)/G2001,"") -> 0.51594488 | R2001: =IF(AND(COUNTIF($A$2:$A$2027,A2001)>1,COUNTIF($A$2:A2001,A2001)=1),1,0) -> 0 | S2001: =IFERROR(VLOOKUP(D2001,Products!$A$2:$F$61,6,FALSE()),"") -> TRUE | T2001: =IF(COUNTIF(Customers!$A$2:$A$301,C2001)=0,"Missing","OK") -> OK | U2001: =IF(K2001="","",PROPER(TRIM(K2001))) -> Delhi | V2001: =IF(AND(U2001="Bengaluru",L2001="Grocery"),I2001,0) -> 0
L2002: =IFERROR(VLOOKUP(D2002,Products!$A$2:$F$61,3,FALSE()),"") | M2002: =IFERROR(VLOOKUP(E2002,Sales_Reps!$A$2:$C$31,3,FALSE()),"") | N2002: =IFERROR(VLOOKUP(D2002,Products!$A$2:$F$61,4,FALSE()),"") | O2002: =IFERROR(VLOOKUP(C2002,Customers!$A$2:$F$301,5,FALSE()),"") | P2002: =IFERROR(VLOOKUP(C2002,Customers!$A$2:$F$301,3,FALSE()),"") | Q2002: =IFERROR((G2002-N2002)/G2002,"") | R2002: =IF(AND(COUNTIF($A$2:$A$2027,A2002)>1,COUNTIF($A$2:A2002,A2002)=1),1,0) -> 0 | S2002: =IFERROR(VLOOKUP(D2002,Products!$A$2:$F$61,6,FALSE()),"") | T2002: =IF(COUNTIF(Customers!$A$2:$A$301,C2002)=0,"Missing","OK") -> Missing | U2002: =IF(K2002="","",PROPER(TRIM(K2002))) | V2002: =IF(AND(U2002="Bengaluru",L2002="Grocery"),I2002,0) -> 0
L2003: =IFERROR(VLOOKUP(D2003,Products!$A$2:$F$61,3,FALSE()),"") | M2003: =IFERROR(VLOOKUP(E2003,Sales_Reps!$A$2:$C$31,3,FALSE()),"") | N2003: =IFERROR(VLOOKUP(D2003,Products!$A$2:$F$61,4,FALSE()),"") | O2003: =IFERROR(VLOOKUP(C2003,Customers!$A$2:$F$301,5,FALSE()),"") | P2003: =IFERROR(VLOOKUP(C2003,Customers!$A$2:$F$301,3,FALSE()),"") | Q2003: =IFERROR((G2003-N2003)/G2003,"") | R2003: =IF(AND(COUNTIF($A$2:$A$2027,A2003)>1,COUNTIF($A$2:A2003,A2003)=1),1,0) -> 0 | S2003: =IFERROR(VLOOKUP(D2003,Products!$A$2:$F$61,6,FALSE()),"") | T2003: =IF(COUNTIF(Customers!$A$2:$A$301,C2003)=0,"Missing","OK") -> Missing | U2003: =IF(K2003="","",PROPER(TRIM(K2003))) | V2003: =IF(AND(U2003="Bengaluru",L2003="Grocery"),I2003,0) -> 0
L2004: =IFERROR(VLOOKUP(D2004,Products!$A$2:$F$61,3,FALSE()),"") | M2004: =IFERROR(VLOOKUP(E2004,Sales_Reps!$A$2:$C$31,3,FALSE()),"") | N2004: =IFERROR(VLOOKUP(D2004,Products!$A$2:$F$61,4,FALSE()),"") | O2004: =IFERROR(VLOOKUP(C2004,Customers!$A$2:$F$301,5,FALSE()),"") | P2004: =IFERROR(VLOOKUP(C2004,Customers!$A$2:$F$301,3,FALSE()),"") | Q2004: =IFERROR((G2004-N2004)/G2004,"") | R2004: =IF(AND(COUNTIF($A$2:$A$2027,A2004)>1,COUNTIF($A$2:A2004,A2004)=1),1,0) -> 0 | S2004: =IFERROR(VLOOKUP(D2004,Products!$A$2:$F$61,6,FALSE()),"") | T2004: =IF(COUNTIF(Customers!$A$2:$A$301,C2004)=0,"Missing","OK") -> Missing | U2004: =IF(K2004="","",PROPER(TRIM(K2004))) | V2004: =IF(AND(U2004="Bengaluru",L2004="Grocery"),I2004,0) -> 0
L2005: =IFERROR(VLOOKUP(D2005,Products!$A$2:$F$61,3,FALSE()),"") | M2005: =IFERROR(VLOOKUP(E2005,Sales_Reps!$A$2:$C$31,3,FALSE()),"") | N2005: =IFERROR(VLOOKUP(D2005,Products!$A$2:$F$61,4,FALSE()),"") | O2005: =IFERROR(VLOOKUP(C2005,Customers!$A$2:$F$301,5,FALSE()),"") | P2005: =IFERROR(VLOOKUP(C2005,Customers!$A$2:$F$301,3,FALSE()),"") | Q2005: =IFERROR((G2005-N2005)/G2005,"") | R2005: =IF(AND(COUNTIF($A$2:$A$2027,A2005)>1,COUNTIF($A$2:A2005,A2005)=1),1,0) -> 0 | S2005: =IFERROR(VLOOKUP(D2005,Products!$A$2:$F$61,6,FALSE()),"") | T2005: =IF(COUNTIF(Customers!$A$2:$A$301,C2005)=0,"Missing","OK") -> Missing | U2005: =IF(K2005="","",PROPER(TRIM(K2005))) | V2005: =IF(AND(U2005="Bengaluru",L2005="Grocery"),I2005,0) -> 0
L2006: =IFERROR(VLOOKUP(D2006,Products!$A$2:$F$61,3,FALSE()),"") | M2006: =IFERROR(VLOOKUP(E2006,Sales_Reps!$A$2:$C$31,3,FALSE()),"") | N2006: =IFERROR(VLOOKUP(D2006,Products!$A$2:$F$61,4,FALSE()),"") | O2006: =IFERROR(VLOOKUP(C2006,Customers!$A$2:$F$301,5,FALSE()),"") | P2006: =IFERROR(VLOOKUP(C2006,Customers!$A$2:$F$301,3,FALSE()),"") | Q2006: =IFERROR((G2006-N2006)/G2006,"") | R2006: =IF(AND(COUNTIF($A$2:$A$2027,A2006)>1,COUNTIF($A$2:A2006,A2006)=1),1,0) -> 0 | S2006: =IFERROR(VLOOKUP(D2006,Products!$A$2:$F$61,6,FALSE()),"") | T2006: =IF(COUNTIF(Customers!$A$2:$A$301,C2006)=0,"Missing","OK") -> Missing | U2006: =IF(K2006="","",PROPER(TRIM(K2006))) | V2006: =IF(AND(U2006="Bengaluru",L2006="Grocery"),I2006,0) -> 0
L2007: =IFERROR(VLOOKUP(D2007,Products!$A$2:$F$61,3,FALSE()),"") | M2007: =IFERROR(VLOOKUP(E2007,Sales_Reps!$A$2:$C$31,3,FALSE()),"") | N2007: =IFERROR(VLOOKUP(D2007,Products!$A$2:$F$61,4,FALSE()),"") | O2007: =IFERROR(VLOOKUP(C2007,Customers!$A$2:$F$301,5,FALSE()),"") | P2007: =IFERROR(VLOOKUP(C2007,Customers!$A$2:$F$301,3,FALSE()),"") | Q2007: =IFERROR((G2007-N2007)/G2007,"") | R2007: =IF(AND(COUNTIF($A$2:$A$2027,A2007)>1,COUNTIF($A$2:A2007,A2007)=1),1,0) -> 0 | S2007: =IFERROR(VLOOKUP(D2007,Products!$A$2:$F$61,6,FALSE()),"") | T2007: =IF(COUNTIF(Customers!$A$2:$A$301,C2007)=0,"Missing","OK") -> Missing | U2007: =IF(K2007="","",PROPER(TRIM(K2007))) | V2007: =IF(AND(U2007="Bengaluru",L2007="Grocery"),I2007,0) -> 0
L2008: =IFERROR(VLOOKUP(D2008,Products!$A$2:$F$61,3,FALSE()),"") | M2008: =IFERROR(VLOOKUP(E2008,Sales_Reps!$A$2:$C$31,3,FALSE()),"") | N2008: =IFERROR(VLOOKUP(D2008,Products!$A$2:$F$61,4,FALSE()),"") | O2008: =IFERROR(VLOOKUP(C2008,Customers!$A$2:$F$301,5,FALSE()),"") | P2008: =IFERROR(VLOOKUP(C2008,Customers!$A$2:$F$301,3,FALSE()),"") | Q2008: =IFERROR((G2008-N2008)/G2008,"") | R2008: =IF(AND(COUNTIF($A$2:$A$2027,A2008)>1,COUNTIF($A$2:A2008,A2008)=1),1,0) -> 0 | S2008: =IFERROR(VLOOKUP(D2008,Products!$A$2:$F$61,6,FALSE()),"") | T2008: =IF(COUNTIF(Customers!$A$2:$A$301,C2008)=0,"Missing","OK") -> Missing | U2008: =IF(K2008="","",PROPER(TRIM(K2008))) | V2008: =IF(AND(U2008="Bengaluru",L2008="Grocery"),I2008,0) -> 0
L2009: =IFERROR(VLOOKUP(D2009,Products!$A$2:$F$61,3,FALSE()),"") | M2009: =IFERROR(VLOOKUP(E2009,Sales_Reps!$A$2:$C$31,3,FALSE()),"") | N2009: =IFERROR(VLOOKUP(D2009,Products!$A$2:$F$61,4,FALSE()),"") | O2009: =IFERROR(VLOOKUP(C2009,Customers!$A$2:$F$301,5,FALSE()),"") | P2009: =IFERROR(VLOOKUP(C2009,Customers!$A$2:$F$301,3,FALSE()),"") | Q2009: =IFERROR((G2009-N2009)/G2009,"") | R2009: =IF(AND(COUNTIF($A$2:$A$2027,A2009)>1,COUNTIF($A$2:A2009,A2009)=1),1,0) -> 0 | S2009: =IFERROR(VLOOKUP(D2009,Products!$A$2:$F$61,6,FALSE()),"") | T2009: =IF(COUNTIF(Customers!$A$2:$A$301,C2009)=0,"Missing","OK") -> Missing | U2009: =IF(K2009="","",PROPER(TRIM(K2009))) | V2009: =IF(AND(U2009="Bengaluru",L2009="Grocery"),I2009,0) -> 0
L2010: =IFERROR(VLOOKUP(D2010,Products!$A$2:$F$61,3,FALSE()),"") | M2010: =IFERROR(VLOOKUP(E2010,Sales_Reps!$A$2:$C$31,3,FALSE()),"") | N2010: =IFERROR(VLOOKUP(D2010,Products!$A$2:$F$61,4,FALSE()),"") | O2010: =IFERROR(VLOOKUP(C2010,Customers!$A$2:$F$301,5,FALSE()),"") | P2010: =IFERROR(VLOOKUP(C2010,Customers!$A$2:$F$301,3,FALSE()),"") | Q2010: =IFERROR((G2010-N2010)/G2010,"") | R2010: =IF(AND(COUNTIF($A$2:$A$2027,A2010)>1,COUNTIF($A$2:A2010,A2010)=1),1,0) -> 0 | S2010: =IFERROR(VLOOKUP(D2010,Products!$A$2:$F$61,6,FALSE()),"") | T2010: =IF(COUNTIF(Customers!$A$2:$A$301,C2010)=0,"Missing","OK") -> Missing | U2010: =IF(K2010="","",PROPER(TRIM(K2010))) | V2010: =IF(AND(U2010="Bengaluru",L2010="Grocery"),I2010,0) -> 0
L2011: =IFERROR(VLOOKUP(D2011,Products!$A$2:$F$61,3,FALSE()),"") | M2011: =IFERROR(VLOOKUP(E2011,Sales_Reps!$A$2:$C$31,3,FALSE()),"") | N2011: =IFERROR(VLOOKUP(D2011,Products!$A$2:$F$61,4,FALSE()),"") | O2011: =IFERROR(VLOOKUP(C2011,Customers!$A$2:$F$301,5,FALSE()),"") | P2011: =IFERROR(VLOOKUP(C2011,Customers!$A$2:$F$301,3,FALSE()),"") | Q2011: =IFERROR((G2011-N2011)/G2011,"") | R2011: =IF(AND(COUNTIF($A$2:$A$2027,A2011)>1,COUNTIF($A$2:A2011,A2011)=1),1,0) -> 0 | S2011: =IFERROR(VLOOKUP(D2011,Products!$A$2:$F$61,6,FALSE()),"") | T2011: =IF(COUNTIF(Customers!$A$2:$A$301,C2011)=0,"Missing","OK") -> Missing | U2011: =IF(K2011="","",PROPER(TRIM(K2011))) | V2011: =IF(AND(U2011="Bengaluru",L2011="Grocery"),I2011,0) -> 0
L2012: =IFERROR(VLOOKUP(D2012,Products!$A$2:$F$61,3,FALSE()),"") | M2012: =IFERROR(VLOOKUP(E2012,Sales_Reps!$A$2:$C$31,3,FALSE()),"") | N2012: =IFERROR(VLOOKUP(D2012,Products!$A$2:$F$61,4,FALSE()),"") | O2012: =IFERROR(VLOOKUP(C2012,Customers!$A$2:$F$301,5,FALSE()),"") | P2012: =IFERROR(VLOOKUP(C2012,Customers!$A$2:$F$301,3,FALSE()),"") | Q2012: =IFERROR((G2012-N2012)/G2012,"") | R2012: =IF(AND(COUNTIF($A$2:$A$2027,A2012)>1,COUNTIF($A$2:A2012,A2012)=1),1,0) -> 0 | S2012: =IFERROR(VLOOKUP(D2012,Products!$A$2:$F$61,6,FALSE()),"") | T2012: =IF(COUNTIF(Customers!$A$2:$A$301,C2012)=0,"Missing","OK") -> Missing | U2012: =IF(K2012="","",PROPER(TRIM(K2012))) | V2012: =IF(AND(U2012="Bengaluru",L2012="Grocery"),I2012,0) -> 0
L2013: =IFERROR(VLOOKUP(D2013,Products!$A$2:$F$61,3,FALSE()),"") | M2013: =IFERROR(VLOOKUP(E2013,Sales_Reps!$A$2:$C$31,3,FALSE()),"") | N2013: =IFERROR(VLOOKUP(D2013,Products!$A$2:$F$61,4,FALSE()),"") | O2013: =IFERROR(VLOOKUP(C2013,Customers!$A$2:$F$301,5,FALSE()),"") | P2013: =IFERROR(VLOOKUP(C2013,Customers!$A$2:$F$301,3,FALSE()),"") | Q2013: =IFERROR((G2013-N2013)/G2013,"") | R2013: =IF(AND(COUNTIF($A$2:$A$2027,A2013)>1,COUNTIF($A$2:A2013,A2013)=1),1,0) -> 0 | S2013: =IFERROR(VLOOKUP(D2013,Products!$A$2:$F$61,6,FALSE()),"") | T2013: =IF(COUNTIF(Customers!$A$2:$A$301,C2013)=0,"Missing","OK") -> Missing | U2013: =IF(K2013="","",PROPER(TRIM(K2013))) | V2013: =IF(AND(U2013="Bengaluru",L2013="Grocery"),I2013,0) -> 0
... L2027: =IFERROR(VLOOKUP(D2027,Products!$A$2:$F$61,3,FALSE()),"") | M2027: =IFERROR(VLOOKUP(E2027,Sales_Reps!$A$2:$C$31,3,FALSE()),"") | N2027: =IFERROR(VLOOKUP(D2027,Products!$A$2:$F$61,4,FALSE()),"") | O2027: =IFERROR(VLOOKUP(C2027,Customers!$A$2:$F$301,5,FALSE()),"") | P2027: =IFERROR(VLOOKUP(C2027,Customers!$A$2:$F$301,3,FALSE()),"") | Q2027: =IFERROR((G2027-N2027)/G2027,"") | R2027: =IF(AND(COUNTIF($A$2:$A$2027,A2027)>1,COUNTIF($A$2:A2027,A2027)=1),1,0) -> 0 | S2027: =IFERROR(VLOOKUP(D2027,Products!$A$2:$F$61,6,FALSE()),"") | T2027: =IF(COUNTIF(Customers!$A$2:$A$301,C2027)=0,"Missing","OK") -> Missing | U2027: =IF(K2027="","",PROPER(TRIM(K2027))) | V2027: =IF(AND(U2027="Bengaluru",L2027="Grocery"),I2027,0) -> 0

Sheet Customers
A1: customer_id | B1: customer_name | C1: age | D1: city | E1: segment | F1: signup_date | G1: Standardized City
A2: CUST-0001 | B2: Amit Agarwal | C2: 36 | D2: Pune | E2: Retail | F2: 44819 | G2: =IF(D2="","",PROPER(TRIM(D2))) -> Pune
A3: CUST-0002 | B3: Vihaan Malhotra | C3: 42 | D3: Pune | E3: Corporate | F3: 44984 | G3: =IF(D3="","",PROPER(TRIM(D3))) -> Pune
A4: CUST-0003 | B4: Navya Malhotra | C4: 33 | D4: Mumbai | E4: Retail | F4: 44059 | G4: =IF(D4="","",PROPER(TRIM(D4))) -> Mumbai
A5: CUST-0004 | B5: Aaradhya Mehta | C5: 53 | D5: delhi | E5: Retail | F5: 44054 | G5: =IF(D5="","",PROPER(TRIM(D5))) -> Delhi
A6: CUST-0005 | B6: Myra Malhotra | C6: 52 | D6: Chennai | E6: Corporate | F6: 45037 | G6: =IF(D6="","",PROPER(TRIM(D6))) -> Chennai
A7: CUST-0006 | B7: Shaurya Iyer | C7: 44 | D7: Pune | E7: SMB | F7: 44302 | G7: =IF(D7="","",PROPER(TRIM(D7))) -> Pune
A8: CUST-0007 | B8: Dhruv Joshi | C8: 47 | D8: Bengaluru | E8: Retail | F8: 44498 | G8: =IF(D8="","",PROPER(TRIM(D8))) -> Bengaluru
A9: CUST-0008 | B9: Kavita Malhotra | C9: 39 | D9: Pune | E9: SMB | F9: 45162 | G9: =IF(D9="","",PROPER(TRIM(D9))) -> Pune
A10: CUST-0009 | B10: Neha Malhotra | C10: 61 | D10: Mumbai | E10: Retail | F10: 44343 | G10: =IF(D10="","",PROPER(TRIM(D10))) -> Mumbai
A11: CUST-0010 | B11: Aaradhya Gupta | C11: 61 | D11: Mumbai | E11: SMB | F11: 44975 | G11: =IF(D11="","",PROPER(TRIM(D11))) -> Mumbai
A12: CUST-0011 | B12: Diya Menon | C12: 41 | D12: Chennai | E12: Corporate | F12: 44821 | G12: =IF(D12="","",PROPER(TRIM(D12))) -> Chennai
A13: CUST-0012 | B13: Prisha Desai | C13: 43 | D13: Pune | E13: Retail | F13: 44718 | G13: =IF(D13="","",PROPER(TRIM(D13))) -> Pune
... A301: CUST-0300 | B301: Rohit Nair | C301: 38 | D301: Mumbai | E301: Retail | F301: 43932 | G301: =IF(D301="","",PROPER(TRIM(D301))) -> Mumbai

Sheet Products
A1: product_id | B1: product_name | C1: category | D1: unit_cost | E1: unit_price | F1: is_active
A2: PROD-001 | B2: Smartphone Pro | C2: Electronics | D2: 2405 | E2: 5330 | F2: =TRUE() -> TRUE
A3: PROD-002 | B3: Wireless Earbuds | C3: Electronics | D3: 1052 | E3: 2600 | F3: =TRUE() -> TRUE
A4: PROD-003 | B4: Smart Watch | C4: Electronics | D4: 1665 | E4: 3570 | F4: =TRUE() -> TRUE
A5: PROD-004 | B5: Laptop Bag | C5: Electronics | D5: 1559 | E5: 3870 | F5: =TRUE() -> TRUE
A6: PROD-005 | B6: Power Bank | C6: Electronics | D6: 128 | E6: 300 | F6: =TRUE() -> TRUE
A7: PROD-006 | B7: Bluetooth Speaker | C7: Electronics | D7: 2865 | E7: 3970 | F7: =TRUE() -> TRUE
A8: PROD-007 | B8: USB-C Cable | C8: Electronics | D8: 861 | E8: 1430 | F8: =TRUE() -> TRUE
A9: PROD-008 | B9: Wireless Mouse | C9: Electronics | D9: 1259 | E9: 2660 | F9: =FALSE() -> FALSE
A10: PROD-009 | B10: Mechanical Keyboard | C10: Electronics | D10: 517 | E10: 1220 | F10: =TRUE() -> TRUE
A11: PROD-010 | B11: Tablet Stand | C11: Electronics | D11: 1149 | E11: 2640 | F11: =TRUE() -> TRUE
A12: PROD-011 | B12: Cotton T-Shirt | C12: Apparel | D12: 1748 | E12: 3450 | F12: =TRUE() -> TRUE
A13: PROD-012 | B13: Denim Jeans | C13: Apparel | D13: 1886 | E13: 3160 | F13: =TRUE() -> TRUE
A14: PROD-013 | B14: Formal Shirt | C14: Apparel | D14: 2611 | E14: 3640 | F14: =TRUE() -> TRUE
A15: PROD-014 | B15: Winter Jacket | C15: Apparel | D15: 2509 | E15: 3620 | F15: =TRUE() -> TRUE
A16: PROD-015 | B16: Sports Shoes | C16: Apparel | D16: 1962 | E16: 2720 | F16: =TRUE() -> TRUE
A17: PROD-016 | B17: Casual Sneakers | C17: Apparel | D17: 396 | E17: 620 | F17: =TRUE() -> TRUE
A18: PROD-017 | B18: Silk Saree | C18: Apparel | D18: 1075 | E18: 2510 | F18: =FALSE() -> FALSE
A19: PROD-018 | B19: Kurta Set | C19: Apparel | D19: 2629 | E19: 3560 | F19: =TRUE() -> TRUE
A20: PROD-019 | B20: Track Pants | C20: Apparel | D20: 1173 | E20: 2480 | F20: =TRUE() -> TRUE
A21: PROD-020 | B21: Woolen Sweater | C21: Apparel | D21: 391 | E21: 820 | F21: =TRUE() -> TRUE
A22: PROD-021 | B22: Basmati Rice 5kg | C22: Grocery | D22: 1435 | E22: 2760 | F22: =TRUE() -> TRUE
A23: PROD-022 | B23: Wheat Flour 10kg | C23: Grocery | D23: 1412 | E23: 2270 | F23: =TRUE() -> TRUE
A24: PROD-023 | B24: Cooking Oil 5L | C24: Grocery | D24: 1182 | E24: 2380 | F24: =TRUE() -> TRUE
A25: PROD-024 | B25: Turmeric Powder 500g | C25: Grocery | D25: 1203 | E25: 2270 | F25: =TRUE() -> TRUE
A26: PROD-025 | B26: Chili Powder 500g | C26: Grocery | D26: 2911 | E26: 4060 | F26: =TRUE() -> TRUE
A27: PROD-026 | B27: Sugar 5kg | C27: Grocery | D27: 2027 | E27: 4070 | F27: =TRUE() -> TRUE
A28: PROD-027 | B28: Tea Leaves 1kg | C28: Grocery | D28: 2436 | E28: 3780 | F28: =TRUE() -> TRUE
A29: PROD-028 | B29: Coffee Beans 500g | C29: Grocery | D29: 2214 | E29: 3660 | F29: =FALSE() -> FALSE
A30: PROD-029 | B30: Ghee 1L | C30: Grocery | D30: 1010 | E30: 2210 | F30: =TRUE() -> TRUE
A31: PROD-030 | B31: Salt 1kg | C31: Grocery | D31: 434 | E31: 970 | F31: =TRUE() -> TRUE
A32: PROD-031 | B32: Bed Sheet Set | C32: Home | D32: 2135 | E32: 3730 | F32: =TRUE() -> TRUE
A33: PROD-032 | B33: Pillow Cover Pair | C33: Home | D33: 288 | E33: 370 | F33: =TRUE() -> TRUE
A34: PROD-033 | B34: Curtain Set | C34: Home | D34: 1143 | E34: 2030 | F34: =TRUE() -> TRUE
A35: PROD-034 | B35: Kitchen Towel Set | C35: Home | D35: 2459 | E35: 5080 | F35: =TRUE() -> TRUE
A36: PROD-035 | B36: Doormat | C36: Home | D36: 464 | E36: 1090 | F36: =TRUE() -> TRUE
A37: PROD-036 | B37: Wall Clock | C37: Home | D37: 1556 | E37: 3250 | F37: =TRUE() -> TRUE
A38: PROD-037 | B38: Table Lamp | C38: Home | D38: 329 | E38: 660 | F38: =TRUE() -> TRUE
A39: PROD-038 | B39: Storage Box | C39: Home | D39: 2549 | E39: 5490 | F39: =TRUE() -> TRUE
A40: PROD-039 | B40: Photo Frame | C40: Home | D40: 1850 | E40: 4610 | F40: =TRUE() -> TRUE
...

Sheet Sales_Reps
A1: rep_id | B1: rep_name | C1: region | D1: hire_date | E1: team_lead_id
A2: R001 | B2: Rajesh Malhotra | C2: North | D2: 44207
A3: R002 | B3: Sunita Malhotra | C3: North | D3: 44028
A4: R003 | B4: Amit Singh | C4: North | D4: 43651
A5: R004 | B5: Priya Singh | C5: North | D5: 44907
A6: R005 | B6: Vikram Patel | C6: North | D6: 43588 | E6: R001
A7: R006 | B7: Neha Desai | C7: North | D7: 44131 | E7: R001
A8: R007 | B8: Suresh Menon | C8: North | D8: 43493 | E8: R001
A9: R008 | B9: Kavita Patel | C9: North | D9: 44693 | E9: R001
A10: R009 | B10: Manoj Patel | C10: South | D10: 44804 | E10: R002
A11: R010 | B11: Divya Rao | C11: South | D11: 43904 | E11: R002
A12: R011 | B12: Anil Verma | C12: South | D12: 44622 | E12: R002
A13: R012 | B13: Pooja Nair | C13: South | D13: 44890 | E13: R002
A14: R013 | B14: Sanjay Kapoor | C14: South | D14: 45215 | E14: R002
A15: R014 | B15: Ritu Menon | C15: South | D15: 44469 | E15: R002
A16: R015 | B16: Deepak Shah | C16: South | D16: 45231 | E16: R002
A17: R016 | B17: Anjali Chopra | C17: South | D17: 43614 | E17: R002
... A31: R030 | B31: Kiran Bhatt | C31: West | D31: 44506 | E31: R004

Sheet Targets
A1: rep_id | B1: Jan-24 | C1: Feb-24 | D1: Mar-24 | E1: Apr-24 | F1: May-24 | G1: Jun-24 | H1: Jul-24 | I1: Aug-24 | J1: Sep-24 | K1: Oct-24 | L1: Nov-24 | M1: Dec-24
A2: R001 | B2: 231324 | C2: 171682 | D2: 234376 | E2: 326967 | F2: 350588 | G2: 385324 | H2: 307980 | I2: 327947 | J2: 181016 | K2: 374039 | L2: 212805 | M2: 405999
A3: R002 | B3: 438126 | C3: 346266 | D3: 329993 | E3: 370744 | F3: 294660 | G3: 341556 | H3: 151934 | I3: 223794 | J3: 438641 | K3: 344308 | L3: 296172 | M3: 304288
A4: R003 | B4: 358703 | C4: 320519 | D4: 327321 | E4: 298753 | F4: 254636 | G4: 351929 | H4: 264723 | I4: 216459 | J4: 391945 | K4: 362426 | L4: 289199 | M4: 301863
A5: R004 | B5: 389594 | C5: 376422 | D5: 324156 | E5: 420255 | F5: 409107 | G5: 269954 | H5: 179097 | I5: 370568 | J5: 387395 | K5: 243454 | L5: 232530 | M5: 201999
A6: R005 | B6: 436862 | C6: 391158 | D6: 340224 | E6: 170548 | F6: 229390 | G6: 349525 | H6: 154683 | I6: 320848 | J6: 354452 | K6: 377180 | L6: 342347 | M6: 183362
A7: R006 | B7: 348734 | C7: 358191 | D7: 250385 | E7: 219657 | F7: 249365 | G7: 435704 | H7: 260892 | I7: 250741 | J7: 358402 | K7: 379858 | L7: 213280 | M7: 224634
A8: R007 | B8: 280057 | C8: 330342 | D8: 336856 | E8: 227425 | F8: 233647 | G8: 307088 | H8: 370724 | I8: 440008 | J8: 406347 | K8: 217357 | L8: 299289 | M8: 214568
A9: R008 | B9: 252886 | C9: 206057 | D9: 318209 | E9: 411230 | F9: 448660 | G9: 171135 | H9: 305339 | I9: 432264 | J9: 294273 | K9: 371409 | L9: 284207 | M9: 437068
A10: R009 | B10: 268752 | C10: 393256 | D10: 310649 | E10: 246237 | F10: 271287 | G10: 314545 | H10: 406506 | I10: 334930 | J10: 348625 | K10: 408928 | L10: 243749 | M10: 418409
A11: R010 | B11: 384734 | C11: 156698 | D11: 283679 | E11: 276085 | F11: 409270 | G11: 285230 | H11: 304233 | I11: 178221 | J11: 284216 | K11: 287373 | L11: 229082 | M11: 298969
A12: R011 | B12: 186029 | C12: 151419 | D12: 253251 | E12: 379757 | F12: 204209 | G12: 179396 | H12: 378008 | I12: 182649 | J12: 267772 | K12: 350352 | L12: 358042 | M12: 359960
A13: R012 | B13: 352158 | C13: 251181 | D13: 321255 | E13: 300863 | F13: 241731 | G13: 393275 | H13: 313561 | I13: 283604 | J13: 429065 | K13: 194420 | L13: 254168 | M13: 389283
... A31: R030 | B31: 151584 | C31: 221679 | D31: 385157 | E31: 290386 | F31: 236041 | G31: 407985 | H31: 184446 | I31: 342894 | J31: 180344 | K31: 292917 | L31: 314858 | M31: 364057

Sheet Q1_Lookups
A1: Q1 - LOOKUP FUNCTIONS (25 marks total)
A2: VLOOKUP · INDEX-MATCH · Two-way lookup · Chain lookup · Approximate lookup · Self-join
A4: Q# | B4: Question | C4: Marks | D4: Hint | E4: Your Answer | F4: Format | G4: Q1.7 Helper
A5: Q1.1 | B5: For order ORD-00234, what is the customer_id? | C5: 3 | D5: Simple VLOOKUP on Orders sheet. | E5: =VLOOKUP("ORD-00234",Orders!$A$2:$K$2027,3,FALSE()) -> CUST-0173 | F5: CUST-#### | G5: =VLOOKUP("ORD-01234",Orders!$A$2:$K$2027,5,FALSE()) -> R013 | H5: =VLOOKUP(G5,Sales_Reps!$A$2:$C$31,2,FALSE()) -> Sanjay Kapoor | I5: =VLOOKUP(G5,Sales_Reps!$A$2:$C$31,3,FALSE()) -> South
A6: Q1.2 | B6: For order ORD-00456, what is the product_name? (You will need to look up the product_id first, then find its name in Products.) | C6: 3 | D6: Two-step lookup, or nested VLOOKUP. | E6: =VLOOKUP(VLOOKUP("ORD-00456",Orders!$A$2:$K$2027,4,FALSE()),Products!$A$2:$F$61,2,FALSE()) -> Dumbbells 5kg | F6: Text
A7: Q1.3 | B7: For order ORD-00987, what is the rep_name of the sales rep? Note: the rep_name is in a column that appears to the LEFT of what you might look up first. | C7: 3 | D7: VLOOKUP has directional limits - INDEX/MATCH does not. | E7: =INDEX(Sales_Reps!$B$2:$B$31,MATCH(VLOOKUP("ORD-00987",Orders!$A$2:$K$2027,5,FALSE()),Sales_Reps!$A$2:$A$31,0)) -> Nisha Menon | F7: Text
A8: Q1.4 | B8: From the Targets sheet, what is the target value for rep R012 in the month Mar-24? | C8: 4 | D8: Two-way lookup: row = rep_id, column = month. | E8: =INDEX(Targets!$A$2:$M$31,MATCH("R012",Targets!$A$2:$A$31,0),MATCH("Mar-24",Targets!$A$1:$M$1,0)) -> 321255 | F8: Whole number
A9: Q1.5 | B9: For order ORD-01500, what is the CATEGORY of the product ordered? (Chain: order → product_id → category) | C9: 4 | D9: Multi-hop lookup across sheets. | E9: =VLOOKUP(VLOOKUP("ORD-01500",Orders!$A$2:$K$2027,4,FALSE()),Products!$A$2:$F$61,3,FALSE()) -> Electronics | F9: Text
A10: Q1.6 | B10: For order ORD-00789, which DISCOUNT SLAB does it fall in? Use the slab table below (rows 20-24). Slab breakpoints are the LOWER bound of each range. | C10: 3 | D10: Approximate-match VLOOKUP (sort ascending, TRUE / omit last arg). | E10: =VLOOKUP(VLOOKUP("ORD-00789",Orders!$A$2:$H$2027,8,FALSE()),$B$18:$C$21,2,TRUE()) -> Bronze | F10: Text
A11: Q1.7 | B11: For order ORD-01234, in one cell produce the string: "<rep_name> (<sales_region>)" - e.g. "Amit Singh (South)". | C11: 3 | D11: Two lookups joined with & or CONCATENATE. | E11: =H5&" ("&I5&")" -> Sanjay Kapoor (South) | F11: Text
A12: Q1.8 | B12: What is the rep_name of the TEAM LEAD for rep R017? (The Sales_Reps sheet has team_lead_id - you need to self-join to find that person's name.) | C12: 2 | D12: Look up the team_lead_id, then look up THAT id's rep_name. | E12: =INDEX(Sales_Reps!$B$2:$B$31,MATCH(INDEX(Sales_Reps!$E$2:$E$31,MATCH("R017",Sales_Reps!$A$2:$A$31,0)),Sales_Reps!$A$2:$A$31,0)) -> Amit Singh | F12: Text
B15: DISCOUNT SLAB REFERENCE TABLE (use for Q1.6)
B17: Discount % (Lower) | C17: Slab
B18: 0 | C18: Bronze
B19: 5 | C19: Silver
B20: 15 | C20: Gold
B21: 25 | C21: Platinum

Sheet Q2_Cleaning
A1: Q2 - DATA CLEANING & QUALITY DIAGNOSTICS (20 marks total)
A2: Duplicates · Whitespace · Case Inconsistency · Referential Integrity · Discontinued SKUs · Anomaly Patterns
A4: Q# | B4: Question | C4: Marks | D4: Hint | E4: Your Answer | F4: Format
A5: Q2.1 | B5: How many DUPLICATE rows exist in the Orders sheet (i.e., how many order_id values appear more than once)? Count each duplicate as ONE (not the extras). | C5: 3 | D5: COUNTIF > 1, then count. Watch what you're counting - rows or IDs. | E5: =SUM(Orders!$R$2:$R$2027) -> 20 | F5: Whole number
A6: Q2.2 | B6: How many customers in the Customers sheet have LEADING or TRAILING whitespace in their customer_name? | C6: 3 | D6: Compare LEN vs LEN(TRIM). Or use SUMPRODUCT with a boolean. | E6: =SUMPRODUCT(--(LEN(Customers!$B$2:$B$301)<>LEN(TRIM(Customers!$B$2:$B$301)))) -> 15 | F6: Whole number
A7: Q2.3 | B7: The Customers sheet has some cities in inconsistent case (e.g., "mumbai", "MUMBAI", "Mumbai"). How many DISTINCT cities exist AFTER standardizing case? | C7: 3 | D7: Combine PROPER/UPPER with a de-dup count. SUMPRODUCT + 1/COUNTIF trick works. | E7: =SUMPRODUCT((Customers!$G$2:$G$301<>"")/COUNTIF(Customers!$G$2:$G$301,Customers!$G$2:$G$301&"")) -> 6 | F7: Whole number
A8: Q2.4 | B8: How many orders reference a customer_id that DOES NOT EXIST in the Customers sheet? (Broken foreign key) | C8: 4 | D8: Use MATCH with ISNA/ISERROR, then count. | E8: =COUNTIF(Orders!$T$2:$T$2027,"Missing") -> 56 | F8: Whole number
A9: Q2.5 | B9: How many orders reference a product that is currently DISCONTINUED (is_active = FALSE in the Products sheet)? | C9: 3 | D9: VLOOKUP the is_active flag, then count where FALSE. | E9: =COUNTIFS(Orders!$S$2:$S$2027,FALSE()) -> 174 | F9: Whole number
A10: Q2.6 | B10: Find the "suspicious pattern": how many orders have payment_status = "Cancelled" AND a discount_pct > 20%? (This pattern often indicates promo abuse - a real-world diagnostic query.) | C10: 4 | D10: COUNTIFS with two criteria. | E10: =COUNTIFS(Orders!$J$2:$J$2027,"Cancelled",Orders!$H$2:$H$2027,">20") -> 58 | F10: Whole number

Sheet Q3_Aggregation
A1: Q3 - CONDITIONAL AGGREGATION (25 marks total)
A2: SUMIFS · COUNTIFS · AVERAGEIFS · Nested IF logic · Multi-sheet aggregation · Top-N logic
H3: Helper: rep revenue totals
A4: Q# | B4: Question | C4: Marks | D4: Hint | E4: Your Answer | F4: Format | H4: Rep ID | I4: Total Revenue
